Workbook
Name TABLETEST: #REF!
Name UNITPRICE: #REF!
Name INSTOCK: INSTOCK!$C$1:$N$2025
Name LIST: #REF!
Name QTY: #REF!
Name TABLEITEM: TABLEITEM!$B$2:$G$1138
Name TABLE: TABLEITEM!$D$474

Sheet INSTOCK
B1: NO. | C1: DATE | D1: IV No. | E1: PO No. | F1: PC Job | G1: SUPPLIER | H1: ID | I1: QTY | J1: unit | K1: UNIT/Price | L1: group | M1: LIST | N1: Total | O1: Column1 | P1: Column2
B2: 1 | C2: 43101 | D2: ยอดยกมา17 | H2: SPC1012202440 | I2: 12 | K2: 561.6 | L2: =IF(D2<>"",VLOOKUP(H2,TABLEITEM,2,FALSE),"") -> MAT ST | M2: =IF(D2<>"",VLOOKUP(H2,TABLEITEM,3,FALSE),"") -> เหล็กแผ่นขาว4'x8'T1.0 | N2: =INSTOCK!$I2*INSTOCK!$K2 -> 6739.2
B3: 2 | C3: 43101 | D3: ยอดยกมา17 | H3: SPC1212202440 | I3: 104 | K3: 644 | L3: =IF(D3<>"",VLOOKUP(H3,TABLEITEM,2,FALSE),"") -> MAT ST | M3: =IF(D3<>"",VLOOKUP(H3,TABLEITEM,3,FALSE),"") -> เหล็กแผ่นขาว4'x8'T1.2 | N3: =INSTOCK!$I3*INSTOCK!$K3 -> 66976
B4: 3 | C4: 43101 | D4: ยอดยกมา17 | H4: SPC1212201950 | I4: 0 | K4: 570.7 | L4: =IF(D4<>"",VLOOKUP(H4,TABLEITEM,2,FALSE),"") -> MAT ST | M4: =IF(D4<>"",VLOOKUP(H4,TABLEITEM,3,FALSE),"") -> เหล็กแผ่นขาว1220x1950T1.2 | N4: =INSTOCK!$I4*INSTOCK!$K4 -> 0
B5: 4 | C5: 43101 | D5: ยอดยกมา17 | H5: SPC1612202440 | I5: 398 | K5: 857.9 | L5: =IF(D5<>"",VLOOKUP(H5,TABLEITEM,2,FALSE),"") -> MAT ST | M5: =IF(D5<>"",VLOOKUP(H5,TABLEITEM,3,FALSE),"") -> เหล็กแผ่นขาว4'x8'T1.6 | N5: =INSTOCK!$I5*INSTOCK!$K5 -> 341444.2
B6: 5 | C6: 43101 | D6: ยอดยกมา17 | H6: SPC1612203000 | I6: 109 | K6: 1055.7 | L6: =IF(D6<>"",VLOOKUP(H6,TABLEITEM,2,FALSE),"") -> MAT ST | M6: =IF(D6<>"",VLOOKUP(H6,TABLEITEM,3,FALSE),"") -> เหล็กแผ่นขาว4''x3000T1.6 | N6: =INSTOCK!$I6*INSTOCK!$K6 -> 115071.3
B7: 6 | C7: 43101 | D7: ยอดยกมา17 | H7: SPC2012202440 | I7: 286 | K7: 1092 | L7: =IF(D7<>"",VLOOKUP(H7,TABLEITEM,2,FALSE),"") -> MAT ST | M7: =IF(D7<>"",VLOOKUP(H7,TABLEITEM,3,FALSE),"") -> เหล็กแผ่นขาว4'x8'T2.0 | N7: =INSTOCK!$I7*INSTOCK!$K7 -> 312312
B8: 7 | C8: 43101 | D8: ยอดยกมา17 | H8: SPC2012203000 | I8: 146 | K8: 1346 | L8: =IF(D8<>"",VLOOKUP(H8,TABLEITEM,2,FALSE),"") -> MAT ST | M8: =IF(D8<>"",VLOOKUP(H8,TABLEITEM,3,FALSE),"") -> เหล็กแผ่นขาว4''X3000T2.0 | N8: =INSTOCK!$I8*INSTOCK!$K8 -> 196516
B9: 8 | C9: 43101 | D9: ยอดยกมา17 | H9: SPC2312202440 | I9: 119 | K9: 1308 | L9: =IF(D9<>"",VLOOKUP(H9,TABLEITEM,2,FALSE),"") -> MAT ST | M9: =IF(D9<>"",VLOOKUP(H9,TABLEITEM,3,FALSE),"") -> เหล็กแผ่นขาว4'x8'T2.3 | N9: =INSTOCK!$I9*INSTOCK!$K9 -> 155652
B10: 9 | C10: 43101 | D10: ยอดยกมา17 | H10: SPC2612202440 | I10: 14 | K10: 1501.8 | L10: =IF(D10<>"",VLOOKUP(H10,TABLEITEM,2,FALSE),"") -> MAT ST | M10: =IF(D10<>"",VLOOKUP(H10,TABLEITEM,3,FALSE),"") -> เหล็กแผ่นขาว4'x8'T2.6 | N10: =INSTOCK!$I10*INSTOCK!$K10 -> 21025.2
B11: 10 | C11: 43101 | D11: ยอดยกมา17 | H11: SPC3012202440 | I11: 260 | K11: 1685.6 | L11: =IF(D11<>"",VLOOKUP(H11,TABLEITEM,2,FALSE),"") -> MAT ST | M11: =IF(D11<>"",VLOOKUP(H11,TABLEITEM,3,FALSE),"") -> เหล็กแผ่นขาว4'x8'T3.0 | N11: =INSTOCK!$I11*INSTOCK!$K11 -> 438256
B12: 11 | C12: 43101 | D12: ยอดยกมา17 | H12: SPC3212202440 | I12: 8 | K12: 2256 | L12: =IF(D12<>"",VLOOKUP(H12,TABLEITEM,2,FALSE),"") -> MAT ST | M12: =IF(D12<>"",VLOOKUP(H12,TABLEITEM,3,FALSE),"") -> เหล็กแผ่นขาว4'x8'T3.2 | N12: =INSTOCK!$I12*INSTOCK!$K12 -> 18048
B13: 12 | C13: 43101 | D13: ยอดยกมา17 | H13: SPC1603902440 | I13: 84 | K13: 282 | L13: =IF(D13<>"",VLOOKUP(H13,TABLEITEM,2,FALSE),"") -> MAT ST | M13: =IF(D13<>"",VLOOKUP(H13,TABLEITEM,3,FALSE),"") -> เหล็กแผ่นขาว390x2440T1.6 | N13: =INSTOCK!$I13*INSTOCK!$K13 -> 23688
... B17: 16 | C17: 43101 | D17: ยอดยกมา17 | H17: SPC1608291942 | I17: 148 | K17: 472.4 | L17: =IF(D17<>"",VLOOKUP(H17,TABLEITEM,2,FALSE),"") -> MAT ST | M17: =IF(D17<>"",VLOOKUP(H17,TABLEITEM,3,FALSE),"") -> เหล็กแผ่นขาว829x1942T1.6 | N17: =INSTOCK!$I17*INSTOCK!$K17 -> 69915.2
B18: 17 | C18: 43101 | D18: ยอดยกมา17 | H18: SPC1609291220 | I18: 54 | L18: =IF(D18<>"",VLOOKUP(H18,TABLEITEM,2,FALSE),"") -> MAT ST | M18: =IF(D18<>"",VLOOKUP(H18,TABLEITEM,3,FALSE),"") -> เหล็กแผ่นขาว929x1220T1.6 | N18: =INSTOCK!$I18*INSTOCK!$K18 -> 0
B19: 18 | C19: 43101 | D19: ยอดยกมา17 | H19: SPC1606292142 | I19: 127 | K19: 394.8 | L19: =IF(D19<>"",VLOOKUP(H19,TABLEITEM,2,FALSE),"") -> MAT ST | M19: =IF(D19<>"",VLOOKUP(H19,TABLEITEM,3,FALSE),"") -> เหล็กแผ่นขาว629x2142T1.6 | N19: =INSTOCK!$I19*INSTOCK!$K19 -> 50139.6
B20: 19 | C20: 43101 | D20: ยอดยกมา17 | H20: SPC1607292142 | I20: 61 | K20: 524.1 | L20: =IF(D20<>"",VLOOKUP(H20,TABLEITEM,2,FALSE),"") -> MAT ST | M20: =IF(D20<>"",VLOOKUP(H20,TABLEITEM,3,FALSE),"") -> เหล็กแผ่นขาว729x2142T1.6 | N20: =INSTOCK!$I20*INSTOCK!$K20 -> 31970.1
B21: 20 | C21: 43101 | D21: ยอดยกมา17 | H21: SPC1608292142 | I21: 56 | K21: 528.4 | L21: =IF(D21<>"",VLOOKUP(H21,TABLEITEM,2,FALSE),"") -> MAT ST | M21: =IF(D21<>"",VLOOKUP(H21,TABLEITEM,3,FALSE),"") -> เหล็กแผ่นขาว829x2142T1.6 | N21: =INSTOCK!$I21*INSTOCK!$K21 -> 29590.4
B22: 21 | C22: 43101 | D22: ยอดยกมา17 | H22: SPC1612202142 | I22: 44 | K22: 860 | L22: =IF(D22<>"",VLOOKUP(H22,TABLEITEM,2,FALSE),"") -> MAT ST | M22: =IF(D22<>"",VLOOKUP(H22,TABLEITEM,3,FALSE),"") -> เหล็กแผ่นขาว1220x2142T1.6 | N22: =INSTOCK!$I22*INSTOCK!$K22 -> 37840
B23: 22 | C23: 43101 | D23: ยอดยกมา17 | H23: SPC1609292142 | I23: 57 | K23: 585.2 | L23: =IF(D23<>"",VLOOKUP(H23,TABLEITEM,2,FALSE),"") -> MAT ST | M23: =IF(D23<>"",VLOOKUP(H23,TABLEITEM,3,FALSE),"") -> เหล็กแผ่นขาว929x2142T1.6 | N23: =INSTOCK!$I23*INSTOCK!$K23 -> 33356.4
B24: 23 | C24: 43101 | D24: ยอดยกมา17 | H24: SPC3012203000 | I24: 5 | K24: 2206.7 | L24: =IF(D24<>"",VLOOKUP(H24,TABLEITEM,2,FALSE),"") -> MAT ST | M24: =IF(D24<>"",VLOOKUP(H24,TABLEITEM,3,FALSE),"") -> เหล็กแผ่นขาว4''x3000T3.0 | N24: =INSTOCK!$I24*INSTOCK!$K24 -> 11033.5
B25: 24 | C25: 43101 | D25: ยอดยกมา17 | H25: SEG1212202440 | I25: 52 | K25: 778.4 | L25: =IF(D25<>"",VLOOKUP(H25,TABLEITEM,2,FALSE),"") -> MAT ST | M25: =IF(D25<>"",VLOOKUP(H25,TABLEITEM,3,FALSE),"") -> เหล็กแผ่นEG4'x8'T1.2 | N25: =INSTOCK!$I25*INSTOCK!$K25 -> 40476.8
B26: 25 | C26: 43101 | D26: ยอดยกมา17 | H26: SEG1612202440 | I26: 97 | K26: 1022 | L26: =IF(D26<>"",VLOOKUP(H26,TABLEITEM,2,FALSE),"") -> MAT ST | M26: =IF(D26<>"",VLOOKUP(H26,TABLEITEM,3,FALSE),"") -> เหล็กแผ่นEG4'x8'T1.6 | N26: =INSTOCK!$I26*INSTOCK!$K26 -> 99134
B27: 26 | C27: 43101 | D27: ยอดยกมา17 | H27: SEG1612203000 | I27: 109 | K27: 1282.5 | L27: =IF(D27<>"",VLOOKUP(H27,TABLEITEM,2,FALSE),"") -> MAT ST | M27: =IF(D27<>"",VLOOKUP(H27,TABLEITEM,3,FALSE),"") -> เหล็กแผ่นEG4'x3000T1.6 | N27: =INSTOCK!$I27*INSTOCK!$K27 -> 139792.5
B28: 27 | C28: 43101 | D28: ยอดยกมา17 | H28: SEG2012202440 | I28: 209 | K28: 1285.2 | L28: =IF(D28<>"",VLOOKUP(H28,TABLEITEM,2,FALSE),"") -> MAT ST | M28: =IF(D28<>"",VLOOKUP(H28,TABLEITEM,3,FALSE),"") -> เหล็กแผ่นEG4'x8'T2.0 | N28: =INSTOCK!$I28*INSTOCK!$K28 -> 268606.8
B29: 28 | C29: 43101 | D29: ยอดยกมา17 | H29: SEG2012203000 | I29: 144 | K29: 1733 | L29: =IF(D29<>"",VLOOKUP(H29,TABLEITEM,2,FALSE),"") -> MAT ST | M29: =IF(D29<>"",VLOOKUP(H29,TABLEITEM,3,FALSE),"") -> เหล็กแผ่นEG4'x3000T2.0 | N29: =INSTOCK!$I29*INSTOCK!$K29 -> 249552
B30: 29 | C30: 43101 | D30: ยอดยกมา17 | H30: SEG2312202440 | I30: 1 | K30: 1502 | L30: =IF(D30<>"",VLOOKUP(H30,TABLEITEM,2,FALSE),"") -> MAT ST | M30: =IF(D30<>"",VLOOKUP(H30,TABLEITEM,3,FALSE),"") -> เหล็กแผ่นEG4'x8'T2.3 | N30: =INSTOCK!$I30*INSTOCK!$K30 -> 1502
B31: 30 | C31: 43101 | D31: ยอดยกมา17 | H31: SEG2612202440 | I31: 32 | L31: =IF(D31<>"",VLOOKUP(H31,TABLEITEM,2,FALSE),"") -> MAT ST | M31: =IF(D31<>"",VLOOKUP(H31,TABLEITEM,3,FALSE),"") -> เหล็กแผ่นEG4'x8'T2.6 | N31: =INSTOCK!$I31*INSTOCK!$K31 -> 0
B32: 31 | C32: 43101 | D32: ยอดยกมา17 | H32: SEG3012202440 | I32: 34 | K32: 2246.4 | L32: =IF(D32<>"",VLOOKUP(H32,TABLEITEM,2,FALSE),"") -> MAT ST | M32: =IF(D32<>"",VLOOKUP(H32,TABLEITEM,3,FALSE),"") -> เหล็กแผ่นEG4'x8'T3.0 | N32: =INSTOCK!$I32*INSTOCK!$K32 -> 76377.6
B33: 32 | C33: 43101 | D33: ยอดยกมา17 | H33: SEG3012203000 | I33: 25 | K33: 2768 | L33: =IF(D33<>"",VLOOKUP(H33,TABLEITEM,2,FALSE),"") -> MAT ST | M33: =IF(D33<>"",VLOOKUP(H33,TABLEITEM,3,FALSE),"") -> เหล็กแผ่นEG4'x3000T3.0 | N33: =INSTOCK!$I33*INSTOCK!$K33 -> 69200
B34: 33 | C34: 43101 | D34: ยอดยกมา17 | H34: SPH1612202440 | I34: 0 | L34: =IF(D34<>"",VLOOKUP(H34,TABLEITEM,2,FALSE),"") -> MAT ST | M34: =IF(D34<>"",VLOOKUP(H34,TABLEITEM,3,FALSE),"") -> เหล็กแผ่นดำ4'x8'T1.6 | N34: =INSTOCK!$I34*INSTOCK!$K34 -> 0
B35: 34 | C35: 43101 | D35: ยอดยกมา17 | H35: SPH1612203000 | I35: 155 | L35: =IF(D35<>"",VLOOKUP(H35,TABLEITEM,2,FALSE),"") -> MAT ST | M35: =IF(D35<>"",VLOOKUP(H35,TABLEITEM,3,FALSE),"") -> เหล็กแผ่นดำ4''x3000T1.6 | N35: =INSTOCK!$I35*INSTOCK!$K35 -> 0
B36: 35 | C36: 43101 | D36: ยอดยกมา17 | H36: SPH2012202440 | I36: 18 | L36: =IF(D36<>"",VLOOKUP(H36,TABLEITEM,2,FALSE),"") -> MAT ST | M36: =IF(D36<>"",VLOOKUP(H36,TABLEITEM,3,FALSE),"") -> เหล็กแผ่นดำ4'x8'T2.0 | N36: =INSTOCK!$I36*INSTOCK!$K36 -> 0
B37: 36 | C37: 43101 | D37: ยอดยกมา17 | H37: SPH2012203000 | I37: 29 | L37: =IF(D37<>"",VLOOKUP(H37,TABLEITEM,2,FALSE),"") -> MAT ST | M37: =IF(D37<>"",VLOOKUP(H37,TABLEITEM,3,FALSE),"") -> เหล็กแผ่นดำ4'x3000T2.0 | N37: =INSTOCK!$I37*INSTOCK!$K37 -> 0
B38: 37 | C38: 43101 | D38: ยอดยกมา17 | H38: SPH2015253050 | I38: 34 | K38: 1795 | L38: =IF(D38<>"",VLOOKUP(H38,TABLEITEM,2,FALSE),"") -> MAT ST | M38: =IF(D38<>"",VLOOKUP(H38,TABLEITEM,3,FALSE),"") -> เหล็กแผ่นดำ5'x10'T2.0 | N38: =INSTOCK!$I38*INSTOCK!$K38 -> 61030
B39: 38 | C39: 43101 | D39: ยอดยกมา17 | H39: SPH2315253050 | I39: 29 | L39: =IF(D39<>"",VLOOKUP(H39,TABLEITEM,2,FALSE),"") -> MAT ST | M39: =IF(D39<>"",VLOOKUP(H39,TABLEITEM,3,FALSE),"") -> เหล็กแผ่นดำ5'x10'T2.3 | N39: =INSTOCK!$I39*INSTOCK!$K39 -> 0
B40: 39 | C40: 43101 | D40: ยอดยกมา17 | H40: SPH3015253050 | I40: 99 | K40: 2690 | L40: =IF(D40<>"",VLOOKUP(H40,TABLEITEM,2,FALSE),"") -> MAT ST | M40: =IF(D40<>"",VLOOKUP(H40,TABLEITEM,3,FALSE),"") -> เหล็กแผ่นดำ5'x10'T3.0 | N40: =INSTOCK!$I40*INSTOCK!$K40 -> 266310
B41: 40 | C41: 43101 | D41: ยอดยกมา17 | H41: SPH4515253050 | I41: 6 | K41: 3170 | L41: =IF(D41<>"",VLOOKUP(H41,TABLEITEM,2,FALSE),"") -> MAT ST | M41: =IF(D41<>"",VLOOKUP(H41,TABLEITEM,3,FALSE),"") -> เหล็กแผ่นดำ5'x10'T4.5 | N41: =INSTOCK!$I41*INSTOCK!$K41 -> 19020
B42: 41 | C42: 43101 | D42: ยอดยกมา17 | H42: SPH5012202440 | I42: 0 | L42: =IF(D42<>"",VLOOKUP(H42,TABLEITEM,2,FALSE),"") -> MAT ST | M42: =IF(D42<>"",VLOOKUP(H42,TABLEITEM,3,FALSE),"") -> เหล็กแผ่นดำ4'x8'T5.0 | N42: =INSTOCK!$I42*INSTOCK!$K42 -> 0
B43: 42 | C43: 43101 | D43: ยอดยกมา17 | H43: SPH9012202440 | I43: 0 | K43: 4200 | L43: =IF(D43<>"",VLOOKUP(H43,TABLEITEM,2,FALSE),"") -> MAT ST | M43: =IF(D43<>"",VLOOKUP(H43,TABLEITEM,3,FALSE),"") -> เหล็กแผ่นดำ4'x8'T9.0 | N43: =INSTOCK!$I43*INSTOCK!$K43 -> 0
...

Sheet TABLEITEM
A1: INSTOCK
A2: NO. | B2: CODE | C2: GROUP | D2: LIST | E2: unit | F2: LOCATION | G2: MAX | H2: SUM IN | I2: SUM OUT | J2: คงเหลือ | L2: GROUP | M2: กลุ่ม ประเภท
A3: 1 | B3: JHH8546835 | C3: PART | D3: คานเจปรับระดับ854x68x35T3.0 | G3: {=MAX(IF(INSTOCK!$H$2:$H$2025=B3,INSTOCK!$K$2:$K$2025))} -> 0 | H3: =SUM(IF(INSTOCK!$H$2:$H$2025=B3,INSTOCK!$I$2:$I$2025)) -> 0 | I3: =SUM(IF([1]!Table13[ID]=B3,[1]!Table13[QTY])) -> #ERROR! | J3: =TABLEITEM!$H$3:$H$1138-TABLEITEM!$I$3:$I$1138 -> #ERROR! | L3: MAT ST | M3: วัสดุ แผ่นเหล็ก
A4: 2 | B4: SO23206000 | C4: PART | D4: เหล็กท่อกลม 3/4" หนา 2.3 มิล | G4: {=MAX(IF(INSTOCK!$H$2:$H$2025=B4,INSTOCK!$K$2:$K$2025))} -> 37.5 | H4: =SUM(IF(INSTOCK!$H$2:$H$2025=B4,INSTOCK!$I$2:$I$2025)) -> 0 | I4: =SUM(IF([1]!Table13[ID]=B4,[1]!Table13[QTY])) -> #ERROR! | J4: =TABLEITEM!$H$3:$H$1138-TABLEITEM!$I$3:$I$1138 -> #ERROR! | L4: MAT GL | M4: วัสดุ กระจก
A5: 3 | B5: ACB70251020 | C5: PART | D5: คานตัวC 70x25T3.0x1020 | G5: {=MAX(IF(INSTOCK!$H$2:$H$2025=B5,INSTOCK!$K$2:$K$2025))} -> 0 | H5: =SUM(IF(INSTOCK!$H$2:$H$2025=B5,INSTOCK!$I$2:$I$2025)) -> 0 | I5: =SUM(IF([1]!Table13[ID]=B5,[1]!Table13[QTY])) -> #ERROR! | J5: =TABLEITEM!$H$3:$H$1138-TABLEITEM!$I$3:$I$1138 -> #ERROR! | L5: PART | M5: ชิ้นส่วนสำเร็จรูป
A6: 4 | B6: ACB7025420 | C6: PART | D6: คานตัวC 70x25T3.0x420 | G6: {=MAX(IF(INSTOCK!$H$2:$H$2025=B6,INSTOCK!$K$2:$K$2025))} -> 0 | H6: =SUM(IF(INSTOCK!$H$2:$H$2025=B6,INSTOCK!$I$2:$I$2025)) -> 0 | I6: =SUM(IF([1]!Table13[ID]=B6,[1]!Table13[QTY])) -> #ERROR! | J6: =TABLEITEM!$H$3:$H$1138-TABLEITEM!$I$3:$I$1138 -> #ERROR!
A7: 5 | B7: ACB7025495 | C7: PART | D7: คานตัวC 70x25T3.0x495 | G7: {=MAX(IF(INSTOCK!$H$2:$H$2025=B7,INSTOCK!$K$2:$K$2025))} -> 0 | H7: =SUM(IF(INSTOCK!$H$2:$H$2025=B7,INSTOCK!$I$2:$I$2025)) -> 0 | I7: =SUM(IF([1]!Table13[ID]=B7,[1]!Table13[QTY])) -> #ERROR! | J7: =TABLEITEM!$H$3:$H$1138-TABLEITEM!$I$3:$I$1138 -> #ERROR!
A8: 6 | B8: ACB7025520 | C8: PART | D8: คานตัวC 70x25T3.0x520 | G8: {=MAX(IF(INSTOCK!$H$2:$H$2025=B8,INSTOCK!$K$2:$K$2025))} -> 0 | H8: =SUM(IF(INSTOCK!$H$2:$H$2025=B8,INSTOCK!$I$2:$I$2025)) -> 0 | I8: =SUM(IF([1]!Table13[ID]=B8,[1]!Table13[QTY])) -> #ERROR! | J8: =TABLEITEM!$H$3:$H$1138-TABLEITEM!$I$3:$I$1138 -> #ERROR!
A9: 7 | B9: ACB7025620 | C9: PART | D9: คานตัวC 70x25T3.0x620 | G9: {=MAX(IF(INSTOCK!$H$2:$H$2025=B9,INSTOCK!$K$2:$K$2025))} -> 0 | H9: =SUM(IF(INSTOCK!$H$2:$H$2025=B9,INSTOCK!$I$2:$I$2025)) -> 0 | I9: =SUM(IF([1]!Table13[ID]=B9,[1]!Table13[QTY])) -> #ERROR! | J9: =TABLEITEM!$H$3:$H$1138-TABLEITEM!$I$3:$I$1138 -> #ERROR!
A10: 8 | B10: ACB7025720 | C10: PART | D10: คานตัวC 70x25T3.0x720 | G10: {=MAX(IF(INSTOCK!$H$2:$H$2025=B10,INSTOCK!$K$2:$K$2025))} -> 0 | H10: =SUM(IF(INSTOCK!$H$2:$H$2025=B10,INSTOCK!$I$2:$I$2025)) -> 0 | I10: =SUM(IF([1]!Table13[ID]=B10,[1]!Table13[QTY])) -> #ERROR! | J10: =TABLEITEM!$H$3:$H$1138-TABLEITEM!$I$3:$I$1138 -> #ERROR!
A11: 9 | B11: ACB7025790 | C11: PART | D11: คานตัวC 70x25T3.0x790 | G11: {=MAX(IF(INSTOCK!$H$2:$H$2025=B11,INSTOCK!$K$2:$K$2025))} -> 0 | H11: =SUM(IF(INSTOCK!$H$2:$H$2025=B11,INSTOCK!$I$2:$I$2025)) -> 0 | I11: =SUM(IF([1]!Table13[ID]=B11,[1]!Table13[QTY])) -> #ERROR! | J11: =TABLEITEM!$H$3:$H$1138-TABLEITEM!$I$3:$I$1138 -> #ERROR!
A12: 10 | B12: ACB7025795 | C12: PART | D12: คานตัวC 70x25T3.0x795 | G12: {=MAX(IF(INSTOCK!$H$2:$H$2025=B12,INSTOCK!$K$2:$K$2025))} -> 0 | H12: =SUM(IF(INSTOCK!$H$2:$H$2025=B12,INSTOCK!$I$2:$I$2025)) -> 0 | I12: =SUM(IF([1]!Table13[ID]=B12,[1]!Table13[QTY])) -> #ERROR! | J12: =TABLEITEM!$H$3:$H$1138-TABLEITEM!$I$3:$I$1138 -> #ERROR!
A13: 11 | B13: ACB7025820 | C13: PART | D13: คานตัวC 70x25T3.0x820 | G13: {=MAX(IF(INSTOCK!$H$2:$H$2025=B13,INSTOCK!$K$2:$K$2025))} -> 0 | H13: =SUM(IF(INSTOCK!$H$2:$H$2025=B13,INSTOCK!$I$2:$I$2025)) -> 0 | I13: =SUM(IF([1]!Table13[ID]=B13,[1]!Table13[QTY])) -> #ERROR! | J13: =TABLEITEM!$H$3:$H$1138-TABLEITEM!$I$3:$I$1138 -> #ERROR!
A14: 12 | B14: ACB7025895 | C14: PART | D14: คานตัวC 70x25T3.0x895 | G14: {=MAX(IF(INSTOCK!$H$2:$H$2025=B14,INSTOCK!$K$2:$K$2025))} -> 0 | H14: =SUM(IF(INSTOCK!$H$2:$H$2025=B14,INSTOCK!$I$2:$I$2025)) -> 0 | I14: =SUM(IF([1]!Table13[ID]=B14,[1]!Table13[QTY])) -> #ERROR! | J14: =TABLEITEM!$H$3:$H$1138-TABLEITEM!$I$3:$I$1138 -> #ERROR!
A15: 13 | B15: ACB7025920 | C15: PART | D15: คานตัวC 70x25T3.0x920 | G15: {=MAX(IF(INSTOCK!$H$2:$H$2025=B15,INSTOCK!$K$2:$K$2025))} -> 0 | H15: =SUM(IF(INSTOCK!$H$2:$H$2025=B15,INSTOCK!$I$2:$I$2025)) -> 0 | I15: =SUM(IF([1]!Table13[ID]=B15,[1]!Table13[QTY])) -> #ERROR! | J15: =TABLEITEM!$H$3:$H$1138-TABLEITEM!$I$3:$I$1138 -> #ERROR!
A16: 14 | B16: ACB7035790 | C16: PART | D16: คานตัวC 70x35T3.0x790 | G16: {=MAX(IF(INSTOCK!$H$2:$H$2025=B16,INSTOCK!$K$2:$K$2025))} -> 0 | H16: =SUM(IF(INSTOCK!$H$2:$H$2025=B16,INSTOCK!$I$2:$I$2025)) -> 0 | I16: =SUM(IF([1]!Table13[ID]=B16,[1]!Table13[QTY])) -> #ERROR! | J16: =TABLEITEM!$H$3:$H$1138-TABLEITEM!$I$3:$I$1138 -> #ERROR!
A17: 15 | B17: ACB7035794 | C17: PART | D17: คานตัวC 70x35T3.0x794 | G17: {=MAX(IF(INSTOCK!$H$2:$H$2025=B17,INSTOCK!$K$2:$K$2025))} -> 0 | H17: =SUM(IF(INSTOCK!$H$2:$H$2025=B17,INSTOCK!$I$2:$I$2025)) -> 0 | I17: =SUM(IF([1]!Table13[ID]=B17,[1]!Table13[QTY])) -> #ERROR! | J17: =TABLEITEM!$H$3:$H$1138-TABLEITEM!$I$3:$I$1138 -> #ERROR!
... A40: 38 | B40: BR1501400338 | C40: PART | D40: แผ่นเบกไลท์ 140x338 T15 | G40: {=MAX(IF(INSTOCK!$H$2:$H$2025=B40,INSTOCK!$K$2:$K$2025))} -> 440 | H40: =SUM(IF(INSTOCK!$H$2:$H$2025=B40,INSTOCK!$I$2:$I$2025)) -> 0 | I40: =SUM(IF([1]!Table13[ID]=B40,[1]!Table13[QTY])) -> #ERROR! | J40: =TABLEITEM!$H$3:$H$1138-TABLEITEM!$I$3:$I$1138 -> #ERROR!
A41: 39 | B41: BR5012202440 | C41: PART | D41: แผ่นเบกไลท์ 1220x2440T5.0 | E41: ชินโชริ | G41: {=MAX(IF(INSTOCK!$H$2:$H$2025=B41,INSTOCK!$K$2:$K$2025))} -> 3500 | H41: =SUM(IF(INSTOCK!$H$2:$H$2025=B41,INSTOCK!$I$2:$I$2025)) -> 0 | I41: =SUM(IF([1]!Table13[ID]=B41,[1]!Table13[QTY])) -> #ERROR! | J41: =TABLEITEM!$H$3:$H$1138-TABLEITEM!$I$3:$I$1138 -> #ERROR!
A42: 40 | B42: CAB401075 | C42: PART | D42: หมวกตู้ 40x1075 | G42: {=MAX(IF(INSTOCK!$H$2:$H$2025=B42,INSTOCK!$K$2:$K$2025))} -> 0 | H42: =SUM(IF(INSTOCK!$H$2:$H$2025=B42,INSTOCK!$I$2:$I$2025)) -> 0 | I42: =SUM(IF([1]!Table13[ID]=B42,[1]!Table13[QTY])) -> #ERROR! | J42: =TABLEITEM!$H$3:$H$1138-TABLEITEM!$I$3:$I$1138 -> #ERROR!
A43: 41 | B43: CAB401175 | C43: PART | D43: หมวกตู้ 40x1175 | G43: {=MAX(IF(INSTOCK!$H$2:$H$2025=B43,INSTOCK!$K$2:$K$2025))} -> 0 | H43: =SUM(IF(INSTOCK!$H$2:$H$2025=B43,INSTOCK!$I$2:$I$2025)) -> 0 | I43: =SUM(IF([1]!Table13[ID]=B43,[1]!Table13[QTY])) -> #ERROR! | J43: =TABLEITEM!$H$3:$H$1138-TABLEITEM!$I$3:$I$1138 -> #ERROR!
A44: 42 | B44: CAB40275 | C44: PART | D44: หมวกตู้ 40x275 | G44: {=MAX(IF(INSTOCK!$H$2:$H$2025=B44,INSTOCK!$K$2:$K$2025))} -> 0 | H44: =SUM(IF(INSTOCK!$H$2:$H$2025=B44,INSTOCK!$I$2:$I$2025)) -> 0 | I44: =SUM(IF([1]!Table13[ID]=B44,[1]!Table13[QTY])) -> #ERROR! | J44: =TABLEITEM!$H$3:$H$1138-TABLEITEM!$I$3:$I$1138 -> #ERROR!
A45: 43 | B45: CAB40325 | C45: PART | D45: หมวกตู้ 40x325 | G45: {=MAX(IF(INSTOCK!$H$2:$H$2025=B45,INSTOCK!$K$2:$K$2025))} -> 0 | H45: =SUM(IF(INSTOCK!$H$2:$H$2025=B45,INSTOCK!$I$2:$I$2025)) -> 0 | I45: =SUM(IF([1]!Table13[ID]=B45,[1]!Table13[QTY])) -> #ERROR! | J45: =TABLEITEM!$H$3:$H$1138-TABLEITEM!$I$3:$I$1138 -> #ERROR!
A46: 44 | B46: CAB40375 | C46: PART | D46: หมวกตู้ 40x375 | G46: {=MAX(IF(INSTOCK!$H$2:$H$2025=B46,INSTOCK!$K$2:$K$2025))} -> 0 | H46: =SUM(IF(INSTOCK!$H$2:$H$2025=B46,INSTOCK!$I$2:$I$2025)) -> 0 | I46: =SUM(IF([1]!Table13[ID]=B46,[1]!Table13[QTY])) -> #ERROR! | J46: =TABLEITEM!$H$3:$H$1138-TABLEITEM!$I$3:$I$1138 -> #ERROR!
A47: 45 | B47: CAB40475 | C47: PART | D47: หมวกตู้ 40x475 | G47: {=MAX(IF(INSTOCK!$H$2:$H$2025=B47,INSTOCK!$K$2:$K$2025))} -> 0 | H47: =SUM(IF(INSTOCK!$H$2:$H$2025=B47,INSTOCK!$I$2:$I$2025)) -> 0 | I47: =SUM(IF([1]!Table13[ID]=B47,[1]!Table13[QTY])) -> #ERROR! | J47: =TABLEITEM!$H$3:$H$1138-TABLEITEM!$I$3:$I$1138 -> #ERROR!
A48: 46 | B48: CAB40575 | C48: PART | D48: หมวกตู้ 40x575 | G48: {=MAX(IF(INSTOCK!$H$2:$H$2025=B48,INSTOCK!$K$2:$K$2025))} -> 0 | H48: =SUM(IF(INSTOCK!$H$2:$H$2025=B48,INSTOCK!$I$2:$I$2025)) -> 0 | I48: =SUM(IF([1]!Table13[ID]=B48,[1]!Table13[QTY])) -> #ERROR! | J48: =TABLEITEM!$H$3:$H$1138-TABLEITEM!$I$3:$I$1138 -> #ERROR!
A49: 47 | B49: CAB40675 | C49: PART | D49: หมวกตู้ 40x675 | G49: {=MAX(IF(INSTOCK!$H$2:$H$2025=B49,INSTOCK!$K$2:$K$2025))} -> 0 | H49: =SUM(IF(INSTOCK!$H$2:$H$2025=B49,INSTOCK!$I$2:$I$2025)) -> 0 | I49: =SUM(IF([1]!Table13[ID]=B49,[1]!Table13[QTY])) -> #ERROR! | J49: =TABLEITEM!$H$3:$H$1138-TABLEITEM!$I$3:$I$1138 -> #ERROR!
A50: 48 | B50: CAB40775 | C50: PART | D50: หมวกตู้ 40x775 | G50: {=MAX(IF(INSTOCK!$H$2:$H$2025=B50,INSTOCK!$K$2:$K$2025))} -> 0 | H50: =SUM(IF(INSTOCK!$H$2:$H$2025=B50,INSTOCK!$I$2:$I$2025)) -> 0 | I50: =SUM(IF([1]!Table13[ID]=B50,[1]!Table13[QTY])) -> #ERROR! | J50: =TABLEITEM!$H$3:$H$1138-TABLEITEM!$I$3:$I$1138 -> #ERROR!
A51: 49 | B51: CAB40875 | C51: PART | D51: หมวกตู้ 40x875 | G51: {=MAX(IF(INSTOCK!$H$2:$H$2025=B51,INSTOCK!$K$2:$K$2025))} -> 0 | H51: =SUM(IF(INSTOCK!$H$2:$H$2025=B51,INSTOCK!$I$2:$I$2025)) -> 0 | I51: =SUM(IF([1]!Table13[ID]=B51,[1]!Table13[QTY])) -> #ERROR! | J51: =TABLEITEM!$H$3:$H$1138-TABLEITEM!$I$3:$I$1138 -> #ERROR!
A52: 50 | B52: CAB40975 | C52: PART | D52: หมวกตู้ 40x975 | G52: {=MAX(IF(INSTOCK!$H$2:$H$2025=B52,INSTOCK!$K$2:$K$2025))} -> 0 | H52: =SUM(IF(INSTOCK!$H$2:$H$2025=B52,INSTOCK!$I$2:$I$2025)) -> 0 | I52: =SUM(IF([1]!Table13[ID]=B52,[1]!Table13[QTY])) -> #ERROR! | J52: =TABLEITEM!$H$3:$H$1138-TABLEITEM!$I$3:$I$1138 -> #ERROR!
A53: 51 | B53: CAH601075 | C53: PART | D53: หมวกตู้ 60x1075 | G53: {=MAX(IF(INSTOCK!$H$2:$H$2025=B53,INSTOCK!$K$2:$K$2025))} -> 0 | H53: =SUM(IF(INSTOCK!$H$2:$H$2025=B53,INSTOCK!$I$2:$I$2025)) -> 0 | I53: =SUM(IF([1]!Table13[ID]=B53,[1]!Table13[QTY])) -> #ERROR! | J53: =TABLEITEM!$H$3:$H$1138-TABLEITEM!$I$3:$I$1138 -> #ERROR!
... A305: 303 | B305: GL30103X268 | C305: MAT GL | D305: กระจก103X268T3.0 | G305: {=MAX(IF(INSTOCK!$H$2:$H$2025=B305,INSTOCK!$K$2:$K$2025))} -> 25 | H305: =SUM(IF(INSTOCK!$H$2:$H$2025=B305,INSTOCK!$I$2:$I$2025)) -> 0 | I305: =SUM(IF([1]!Table13[ID]=B305,[1]!Table13[QTY])) -> #ERROR! | J305: =TABLEITEM!$H$3:$H$1138-TABLEITEM!$I$3:$I$1138 -> #ERROR!
A306: 304 | B306: GL30108X208 | C306: MAT GL | D306: กระจก108x208T3.0 | E306: แผ่น | G306: {=MAX(IF(INSTOCK!$H$2:$H$2025=B306,INSTOCK!$K$2:$K$2025))} -> 25 | H306: =SUM(IF(INSTOCK!$H$2:$H$2025=B306,INSTOCK!$I$2:$I$2025)) -> 0 | I306: =SUM(IF([1]!Table13[ID]=B306,[1]!Table13[QTY])) -> #ERROR! | J306: =TABLEITEM!$H$3:$H$1138-TABLEITEM!$I$3:$I$1138 -> #ERROR!
A307: 305 | B307: GL30108X308 | C307: MAT GL | D307: กระจก108x308T3.0 | E307: แผ่น | G307: {=MAX(IF(INSTOCK!$H$2:$H$2025=B307,INSTOCK!$K$2:$K$2025))} -> 35 | H307: =SUM(IF(INSTOCK!$H$2:$H$2025=B307,INSTOCK!$I$2:$I$2025)) -> 0 | I307: =SUM(IF([1]!Table13[ID]=B307,[1]!Table13[QTY])) -> #ERROR! | J307: =TABLEITEM!$H$3:$H$1138-TABLEITEM!$I$3:$I$1138 -> #ERROR!
A308: 306 | B308: GL30118X260 | C308: MAT GL | D308: กระจก118x260T3.0 | E308: แผ่น | G308: {=MAX(IF(INSTOCK!$H$2:$H$2025=B308,INSTOCK!$K$2:$K$2025))} -> 25 | H308: =SUM(IF(INSTOCK!$H$2:$H$2025=B308,INSTOCK!$I$2:$I$2025)) -> 0 | I308: =SUM(IF([1]!Table13[ID]=B308,[1]!Table13[QTY])) -> #ERROR! | J308: =TABLEITEM!$H$3:$H$1138-TABLEITEM!$I$3:$I$1138 -> #ERROR!
A309: 307 | B309: GL30118X308 | C309: MAT GL | D309: กระจก118x308T3.0 | E309: แผ่น | G309: {=MAX(IF(INSTOCK!$H$2:$H$2025=B309,INSTOCK!$K$2:$K$2025))} -> 38 | H309: =SUM(IF(INSTOCK!$H$2:$H$2025=B309,INSTOCK!$I$2:$I$2025)) -> 0 | I309: =SUM(IF([1]!Table13[ID]=B309,[1]!Table13[QTY])) -> #ERROR! | J309: =TABLEITEM!$H$3:$H$1138-TABLEITEM!$I$3:$I$1138 -> #ERROR!
A310: 308 | B310: GL30132X132 | C310: MAT GL | D310: กระจก132X132T3.0 | E310: แผ่น | G310: {=MAX(IF(INSTOCK!$H$2:$H$2025=B310,INSTOCK!$K$2:$K$2025))} -> 25 | H310: =SUM(IF(INSTOCK!$H$2:$H$2025=B310,INSTOCK!$I$2:$I$2025)) -> 0 | I310: =SUM(IF([1]!Table13[ID]=B310,[1]!Table13[QTY])) -> #ERROR! | J310: =TABLEITEM!$H$3:$H$1138-TABLEITEM!$I$3:$I$1138 -> #ERROR!
A311: 310 | B311: GL30158X208 | C311: MAT GL | D311: กระจก158x208T3.0 | E311: แผ่น | G311: {=MAX(IF(INSTOCK!$H$2:$H$2025=B311,INSTOCK!$K$2:$K$2025))} -> 25 | H311: =SUM(IF(INSTOCK!$H$2:$H$2025=B311,INSTOCK!$I$2:$I$2025)) -> 0 | I311: =SUM(IF([1]!Table13[ID]=B311,[1]!Table13[QTY])) -> #ERROR! | J311: =TABLEITEM!$H$3:$H$1138-TABLEITEM!$I$3:$I$1138 -> #ERROR!
A312: 311 | B312: GL30158X308 | C312: MAT GL | D312: กระจก158x308T3.0 | E312: แผ่น | G312: {=MAX(IF(INSTOCK!$H$2:$H$2025=B312,INSTOCK!$K$2:$K$2025))} -> 38 | H312: =SUM(IF(INSTOCK!$H$2:$H$2025=B312,INSTOCK!$I$2:$I$2025)) -> 0 | I312: =SUM(IF([1]!Table13[ID]=B312,[1]!Table13[QTY])) -> #ERROR! | J312: =TABLEITEM!$H$3:$H$1138-TABLEITEM!$I$3:$I$1138 -> #ERROR!
A313: 312 | B313: GL30158X408 | C313: MAT GL | D313: กระจก158x408T3.0 | E313: แผ่น | G313: {=MAX(IF(INSTOCK!$H$2:$H$2025=B313,INSTOCK!$K$2:$K$2025))} -> 40 | H313: =SUM(IF(INSTOCK!$H$2:$H$2025=B313,INSTOCK!$I$2:$I$2025)) -> 0 | I313: =SUM(IF([1]!Table13[ID]=B313,[1]!Table13[QTY])) -> #ERROR! | J313: =TABLEITEM!$H$3:$H$1138-TABLEITEM!$I$3:$I$1138 -> #ERROR!
...

Sheet REPORTIN
A1: DATE | B1: 43652 | I1: ID | J1: SEG2312203000
A2: SUPPLIER | B2: (All) | I2: LIST | J2: (All)
A3: IV No. | B3: (All)
A4: PO No. | B4: (All) | L4: Values
A5: PC Job | B5: (All) | I5: SUPPLIER | J5: IV No. | K5: UNIT/Price | L5: Sum of QTY | M5: Sum of Total
I6: เอ็น.เอช.เค.สตีล จำกัด | J6: N61/004696 | K6: 1988.6 | L6: 50 | M6: 99430
C7: Values | J7: N61/004696 Total | L7: 50 | M7: 99430
A8: ID | B8: LIST | C8: Average of UNIT/Price | D8: Sum of QTY | E8: Sum of Total | I8: Grand Total | L8: 50 | M8: 99430
A9: FC6845520 | B9: คานต่อโครง3mm 68x45x520 | D9: 14 | E9: 0
A10: FC6845420 | B10: คานต่อโครง3mm 68x45x420 | D10: 18 | E10: 0
A11: FC6845720 | B11: คานต่อโครง3mm 68x45x720 | D11: 240 | E11: 0
A12: FC6845270 | B12: คานต่อโครง3mm 68x45x270 | D12: 69 | E12: 0
A13: FC8045520 | B13: คานต่อโครง 80x45x3mmx520 | D13: 25 | E13: 0
A14: ACC503429 | B14: ฉากตัวZ รับแผ่นกั้น50x34x29 | D14: 294 | E14: 0
A15: FC6845260 | B15: คานต่อโครง3mm 68x45x260 | D15: 9 | E15: 0
A16: FC8045260 | B16: คานต่อโครง 80x45x3mmx260 | D16: 18 | E16: 0
A17: FC6845620 | B17: คานต่อโครง3mm 68x45x620 | D17: 16 | E17: 0
A18: FC8045620 | B18: คานต่อโครง 80x45x3mmx620 | D18: 8 | E18: 0
A19: FC6845920 | B19: คานต่อโครง3mm 68x45x920 | D19: 1 | E19: 0
A20: FC8045920 | B20: คานต่อโครง 80x45x3mmx920 | D20: 2 | E20: 0
A21: GLN60190X290 | B21: กระจกลวด190X290T6.0 | C21: 450 | D21: 10 | E21: 4500
A22: CAB40875 | B22: หมวกตู้ 40x875 | D22: 5 | E22: 0
A23: Grand Total | C23: 450 | D23: 729 | E23: 4500
