Workbook
Name INSTOCK: INSTOCK!$D$2:$N$6125
Name TABLE: #REF!
Name QTY: #REF!
Name UNITPRICE: #REF!
Name LIST: #REF!
Name TABLEITEM: TABLEITEM!$B$2:$G$2749
Name TABLETEST: #REF!

Sheet INSTOCK
B2: NO. | C2: DATE | D2: IV No. | E2: PO No. | F2: PC Job | G2: SUPPLIER | H2: ID | I2: qty | J2: Column3 | K2: UNIT/Price | L2: group | M2: LIST | N2: Total | O2: Column1 | P2: Column2
B3: 1 | C3: 43199 | D3: ยอดยกมา17 | H3: CG | I3: 102 | J3: =IF(D3<>"",VLOOKUP(H3,TABLEITEM,5,FALSE),"") -> คู่ | K3: 4.58 | L3: =IF(D3<>"",VLOOKUP(H3,TABLEITEM,2,FALSE),"") | M3: =IF(D3<>"",VLOOKUP(H3,TABLEITEM,3,FALSE),"") -> ถุงมือผ้า | N3: =INSTOCK!$I3*INSTOCK!$K3 -> 467.16
B4: 2 | C4: 43199 | D4: ยอดยกมา17 | H4: LG | I4: 13 | J4: =IF(D4<>"",VLOOKUP(H4,TABLEITEM,5,FALSE),"") -> คู่ | K4: 41.66 | L4: =IF(D4<>"",VLOOKUP(H4,TABLEITEM,2,FALSE),"") | M4: =IF(D4<>"",VLOOKUP(H4,TABLEITEM,3,FALSE),"") -> ถุงมือหนัง | N4: =INSTOCK!$I4*INSTOCK!$K4 -> 541.58
B5: 3 | C5: 43199 | D5: ยอดยกมา17 | H5: RP | I5: 195 | J5: =IF(D5<>"",VLOOKUP(H5,TABLEITEM,5,FALSE),"") -> EA | K5: 2.5 | L5: =IF(D5<>"",VLOOKUP(H5,TABLEITEM,2,FALSE),"") | M5: =IF(D5<>"",VLOOKUP(H5,TABLEITEM,3,FALSE),"") -> ผ้าปิดจมูก | N5: =INSTOCK!$I5*INSTOCK!$K5 -> 487.5
B6: 4 | C6: 43199 | D6: ยอดยกมา17 | H6: PVC | I6: 30 | J6: =IF(D6<>"",VLOOKUP(H6,TABLEITEM,5,FALSE),"") -> ROLL | K6: 140 | L6: =IF(D6<>"",VLOOKUP(H6,TABLEITEM,2,FALSE),"") | M6: =IF(D6<>"",VLOOKUP(H6,TABLEITEM,3,FALSE),"") -> พลาสติกห่อตู้ 20micx50cmx300m | N6: =INSTOCK!$I6*INSTOCK!$K6 -> 4200
B7: 5 | C7: 43199 | D7: ยอดยกมา17 | H7: WW | I7: 9 | J7: =IF(D7<>"",VLOOKUP(H7,TABLEITEM,5,FALSE),"") -> ROLL | K7: 750 | L7: =IF(D7<>"",VLOOKUP(H7,TABLEITEM,2,FALSE),"") | M7: =IF(D7<>"",VLOOKUP(H7,TABLEITEM,3,FALSE),"") -> ลวดเชื่อมco2 | N7: =INSTOCK!$I7*INSTOCK!$K7 -> 6750
B8: 6 | C8: 43199 | D8: ยอดยกมา17 | H8: BS | I8: 360 | J8: =IF(D8<>"",VLOOKUP(H8,TABLEITEM,5,FALSE),"") -> EA | K8: 40 | L8: =IF(D8<>"",VLOOKUP(H8,TABLEITEM,2,FALSE),"") | M8: =IF(D8<>"",VLOOKUP(H8,TABLEITEM,3,FALSE),"") -> ใบหินเจียร์ 4'' | N8: =INSTOCK!$I8*INSTOCK!$K8 -> 14400
B9: 7 | C9: 43199 | D9: ยอดยกมา17 | H9: BT80 | I9: 390 | J9: =IF(D9<>"",VLOOKUP(H9,TABLEITEM,5,FALSE),"") -> EA | K9: 42 | L9: =IF(D9<>"",VLOOKUP(H9,TABLEITEM,2,FALSE),"") | M9: =IF(D9<>"",VLOOKUP(H9,TABLEITEM,3,FALSE),"") -> ใบขัดซ้อน # 80 | N9: =INSTOCK!$I9*INSTOCK!$K9 -> 16380
B10: 8 | C10: 43199 | D10: ยอดยกมา17 | H10: BT400 | I10: 110 | J10: =IF(D10<>"",VLOOKUP(H10,TABLEITEM,5,FALSE),"") -> EA | K10: 25 | L10: =IF(D10<>"",VLOOKUP(H10,TABLEITEM,2,FALSE),"") | M10: =IF(D10<>"",VLOOKUP(H10,TABLEITEM,3,FALSE),"") -> ใบขัดซ้อน # 400 | N10: =INSTOCK!$I10*INSTOCK!$K10 -> 2750
B11: 9 | C11: 43199 | D11: ยอดยกมา17 | H11: RS120 | I11: 900 | J11: =IF(D11<>"",VLOOKUP(H11,TABLEITEM,5,FALSE),"") -> EA | K11: 4.5 | L11: =IF(D11<>"",VLOOKUP(H11,TABLEITEM,2,FALSE),"") | M11: =IF(D11<>"",VLOOKUP(H11,TABLEITEM,3,FALSE),"") -> กระดาษทรายกลม#120 | N11: =INSTOCK!$I11*INSTOCK!$K11 -> 4050
B12: 10 | C12: 43199 | D12: ยอดยกมา17 | H12: PW | I12: 10 | J12: =IF(D12<>"",VLOOKUP(H12,TABLEITEM,5,FALSE),"") -> #N/A | K12: 490 | L12: =IF(D12<>"",VLOOKUP(H12,TABLEITEM,2,FALSE),"") -> #N/A | M12: =IF(D12<>"",VLOOKUP(H12,TABLEITEM,3,FALSE),"") -> #N/A | N12: =INSTOCK!$I12*INSTOCK!$K12 -> 4900
B13: 11 | C13: 43199 | D13: ยอดยกมา17 | H13: DC110 | I13: 1200 | J13: =IF(D13<>"",VLOOKUP(H13,TABLEITEM,5,FALSE),"") -> M | K13: 18 | L13: =IF(D13<>"",VLOOKUP(H13,TABLEITEM,2,FALSE),"") | M13: =IF(D13<>"",VLOOKUP(H13,TABLEITEM,3,FALSE),"") -> ยางโปร่ง#110 | N13: =INSTOCK!$I13*INSTOCK!$K13 -> 21600
B14: 12 | C14: 43199 | D14: ยอดยกมา17 | H14: SR 3/4x3/16 | I14: 100 | J14: =IF(D14<>"",VLOOKUP(H14,TABLEITEM,5,FALSE),"") -> M | K14: 12 | L14: =IF(D14<>"",VLOOKUP(H14,TABLEITEM,2,FALSE),"") | M14: =IF(D14<>"",VLOOKUP(H14,TABLEITEM,3,FALSE),"") -> ยางฟองน้ำ 3/4''x3/16'' | N14: =INSTOCK!$I14*INSTOCK!$K14 -> 1200
... B31: 29 | C31: 43199 | D31: ยอดยกมา17 | H31: TN AAA | I31: 3 | J31: =IF(D31<>"",VLOOKUP(H31,TABLEITEM,5,FALSE),"") -> ปี๊ป | K31: 260 | L31: =IF(D31<>"",VLOOKUP(H31,TABLEITEM,2,FALSE),"") | M31: =IF(D31<>"",VLOOKUP(H31,TABLEITEM,3,FALSE),"") -> ทินเนอร์ AAA | N31: =INSTOCK!$I31*INSTOCK!$K31 -> 780
B32: 30 | C32: 43199 | D32: ยอดยกมา17 | H32: PAINT-POUT | I32: 46 | J32: =IF(D32<>"",VLOOKUP(H32,TABLEITEM,5,FALSE),"") -> กล | L32: =IF(D32<>"",VLOOKUP(H32,TABLEITEM,2,FALSE),"") | M32: =IF(D32<>"",VLOOKUP(H32,TABLEITEM,3,FALSE),"") -> สีโป้ว | N32: =INSTOCK!$I32*INSTOCK!$K32 -> 0
B33: 31 | C33: 43199 | D33: ยอดยกมา17 | H33: BW | I33: 12 | J33: =IF(D33<>"",VLOOKUP(H33,TABLEITEM,5,FALSE),"") -> ROLL | K33: 90 | L33: =IF(D33<>"",VLOOKUP(H33,TABLEITEM,2,FALSE),"") | M33: =IF(D33<>"",VLOOKUP(H33,TABLEITEM,3,FALSE),"") -> ลวดดำ | N33: =INSTOCK!$I33*INSTOCK!$K33 -> 1080
B34: 32 | C34: 43199 | D34: ยอดยกมา17 | H34: TSA-W | I34: 18 | J34: =IF(D34<>"",VLOOKUP(H34,TABLEITEM,5,FALSE),"") -> EA | L34: =IF(D34<>"",VLOOKUP(H34,TABLEITEM,2,FALSE),"") | M34: =IF(D34<>"",VLOOKUP(H34,TABLEITEM,3,FALSE),"") -> กระดาษกาว 2หน้าสีขาว | N34: =INSTOCK!$I34*INSTOCK!$K34 -> 0
B35: 33 | C35: 43199 | D35: ยอดยกมา17 | H35: TSA-4 | I35: 13 | J35: =IF(D35<>"",VLOOKUP(H35,TABLEITEM,5,FALSE),"") -> EA | K35: 5.5 | L35: =IF(D35<>"",VLOOKUP(H35,TABLEITEM,2,FALSE),"") | M35: =IF(D35<>"",VLOOKUP(H35,TABLEITEM,3,FALSE),"") -> กระดาษกาว 2หน้า 4มิล | N35: =INSTOCK!$I35*INSTOCK!$K35 -> 71.5
B36: 34 | C36: 43199 | D36: ยอดยกมา17 | H36: TSA-8 | I36: 30 | J36: =IF(D36<>"",VLOOKUP(H36,TABLEITEM,5,FALSE),"") -> EA | K36: 123 | L36: =IF(D36<>"",VLOOKUP(H36,TABLEITEM,2,FALSE),"") | M36: =IF(D36<>"",VLOOKUP(H36,TABLEITEM,3,FALSE),"") -> กระดาษกาว2 หน้า 8 มิล | N36: =INSTOCK!$I36*INSTOCK!$K36 -> 3690
B37: 35 | C37: 43199 | D37: ยอดยกมา17 | H37: TSA-13 | I37: 98 | J37: =IF(D37<>"",VLOOKUP(H37,TABLEITEM,5,FALSE),"") -> EA | K37: 159 | L37: =IF(D37<>"",VLOOKUP(H37,TABLEITEM,2,FALSE),"") | M37: =IF(D37<>"",VLOOKUP(H37,TABLEITEM,3,FALSE),"") -> กระดาษกาว 2 หน้า 13 มิล | N37: =INSTOCK!$I37*INSTOCK!$K37 -> 15582
B38: 36 | C38: 43199 | D38: ยอดยกมา17 | H38: NITT0 | I38: 35 | J38: =IF(D38<>"",VLOOKUP(H38,TABLEITEM,5,FALSE),"") -> EA | K38: 18 | L38: =IF(D38<>"",VLOOKUP(H38,TABLEITEM,2,FALSE),"") | M38: =IF(D38<>"",VLOOKUP(H38,TABLEITEM,3,FALSE),"") -> กระดาษกาวนิตโต้ | N38: =INSTOCK!$I38*INSTOCK!$K38 -> 630
B39: 37 | C39: 43199 | D39: ยอดยกมา17 | H39: GT1 | I39: 16 | J39: =IF(D39<>"",VLOOKUP(H39,TABLEITEM,5,FALSE),"") -> EA | K39: 26 | L39: =IF(D39<>"",VLOOKUP(H39,TABLEITEM,2,FALSE),"") | M39: =IF(D39<>"",VLOOKUP(H39,TABLEITEM,3,FALSE),"") -> กระดาษกาว 1 '' | N39: =INSTOCK!$I39*INSTOCK!$K39 -> 416
B40: 38 | C40: 43199 | D40: ยอดยกมา17 | H40: GT2 | I40: 12 | J40: =IF(D40<>"",VLOOKUP(H40,TABLEITEM,5,FALSE),"") -> EA | K40: 47 | L40: =IF(D40<>"",VLOOKUP(H40,TABLEITEM,2,FALSE),"") | M40: =IF(D40<>"",VLOOKUP(H40,TABLEITEM,3,FALSE),"") -> กระดาษกาว 2 '' | N40: =INSTOCK!$I40*INSTOCK!$K40 -> 564
B41: 39 | C41: 43199 | D41: ยอดยกมา17 | H41: GT3 | I41: 80 | J41: =IF(D41<>"",VLOOKUP(H41,TABLEITEM,5,FALSE),"") -> EA | L41: =IF(D41<>"",VLOOKUP(H41,TABLEITEM,2,FALSE),"") | M41: =IF(D41<>"",VLOOKUP(H41,TABLEITEM,3,FALSE),"") -> กระดาษกาว 3 '' | N41: =INSTOCK!$I41*INSTOCK!$K41 -> 0
B42: 40 | C42: 43199 | D42: ยอดยกมา17 | H42: CAT | I42: 39 | J42: =IF(D42<>"",VLOOKUP(H42,TABLEITEM,5,FALSE),"") -> EA | K42: 35.04 | L42: =IF(D42<>"",VLOOKUP(H42,TABLEITEM,2,FALSE),"") | M42: =IF(D42<>"",VLOOKUP(H42,TABLEITEM,3,FALSE),"") -> เทปใส 2'' | N42: =INSTOCK!$I42*INSTOCK!$K42 -> 1366.56
B43: 41 | C43: 43199 | D43: ยอดยกมา17 | H43: BCT | I43: 63 | J43: =IF(D43<>"",VLOOKUP(H43,TABLEITEM,5,FALSE),"") -> EA | K43: 10 | L43: =IF(D43<>"",VLOOKUP(H43,TABLEITEM,2,FALSE),"") | M43: =IF(D43<>"",VLOOKUP(H43,TABLEITEM,3,FALSE),"") -> เทปพันสายไฟสีดำ | N43: =INSTOCK!$I43*INSTOCK!$K43 -> 630
B44: 42 | C44: 43199 | D44: ยอดยกมา17 | H44: PT | I44: 27 | J44: =IF(D44<>"",VLOOKUP(H44,TABLEITEM,5,FALSE),"") -> EA | K44: 10 | L44: =IF(D44<>"",VLOOKUP(H44,TABLEITEM,2,FALSE),"") | M44: =IF(D44<>"",VLOOKUP(H44,TABLEITEM,3,FALSE),"") -> เทปพันเกลียว | N44: =INSTOCK!$I44*INSTOCK!$K44 -> 270
B45: 43 | C45: 43199 | D45: ยอดยกมา17 | H45: paint-231 | I45: 12 | J45: =IF(D45<>"",VLOOKUP(H45,TABLEITEM,5,FALSE),"") -> กป. | K45: 41.6 | L45: =IF(D45<>"",VLOOKUP(H45,TABLEITEM,2,FALSE),"") | M45: =IF(D45<>"",VLOOKUP(H45,TABLEITEM,3,FALSE),"") -> สีสเปรย์ เคลียร์ | N45: =INSTOCK!$I45*INSTOCK!$K45 -> 499.2
B46: 44 | C46: 43199 | D46: ยอดยกมา17 | H46: SONAX | I46: 5 | J46: =IF(D46<>"",VLOOKUP(H46,TABLEITEM,5,FALSE),"") -> EA | K46: 100 | L46: =IF(D46<>"",VLOOKUP(H46,TABLEITEM,2,FALSE),"") | M46: =IF(D46<>"",VLOOKUP(H46,TABLEITEM,3,FALSE),"") -> โซเน็ก | N46: =INSTOCK!$I46*INSTOCK!$K46 -> 500
B47: 45 | C47: 43199 | D47: ยอดยกมา17 | H47: GLUE | I47: 1 | J47: =IF(D47<>"",VLOOKUP(H47,TABLEITEM,5,FALSE),"") -> EA | K47: 65 | L47: =IF(D47<>"",VLOOKUP(H47,TABLEITEM,2,FALSE),"") | M47: =IF(D47<>"",VLOOKUP(H47,TABLEITEM,3,FALSE),"") -> กาวยาง | N47: =INSTOCK!$I47*INSTOCK!$K47 -> 65
B48: 46 | C48: 43199 | D48: ยอดยกมา17 | H48: paint-211 | I48: 35 | J48: =IF(D48<>"",VLOOKUP(H48,TABLEITEM,5,FALSE),"") -> กป. | K48: 41.6 | L48: =IF(D48<>"",VLOOKUP(H48,TABLEITEM,2,FALSE),"") | M48: =IF(D48<>"",VLOOKUP(H48,TABLEITEM,3,FALSE),"") -> สีสเปรย์ สีแดง | N48: =INSTOCK!$I48*INSTOCK!$K48 -> 1456
B49: 47 | C49: 43199 | D49: ยอดยกมา17 | H49: paint-216 | I49: 32 | J49: =IF(D49<>"",VLOOKUP(H49,TABLEITEM,5,FALSE),"") -> กป. | K49: 41.6 | L49: =IF(D49<>"",VLOOKUP(H49,TABLEITEM,2,FALSE),"") | M49: =IF(D49<>"",VLOOKUP(H49,TABLEITEM,3,FALSE),"") -> สีสเปรย์ สีน้ำเงิน | N49: =INSTOCK!$I49*INSTOCK!$K49 -> 1331.2
B50: 48 | C50: 43199 | D50: ยอดยกมา17 | H50: paint-200 | I50: 28 | J50: =IF(D50<>"",VLOOKUP(H50,TABLEITEM,5,FALSE),"") -> กป. | K50: 41.6 | L50: =IF(D50<>"",VLOOKUP(H50,TABLEITEM,2,FALSE),"") | M50: =IF(D50<>"",VLOOKUP(H50,TABLEITEM,3,FALSE),"") -> สีสเปรย์ สีขาว | N50: =INSTOCK!$I50*INSTOCK!$K50 -> 1164.8
B51: 49 | C51: 43199 | D51: ยอดยกมา17 | H51: paint-218 | I51: 24 | J51: =IF(D51<>"",VLOOKUP(H51,TABLEITEM,5,FALSE),"") -> กป. | K51: 41.6 | L51: =IF(D51<>"",VLOOKUP(H51,TABLEITEM,2,FALSE),"") | M51: =IF(D51<>"",VLOOKUP(H51,TABLEITEM,3,FALSE),"") -> สีสเปรย์ สีเหลือง | N51: =INSTOCK!$I51*INSTOCK!$K51 -> 998.4
B52: 50 | C52: 43199 | D52: ยอดยกมา17 | H52: paint-214 | I52: 7 | J52: =IF(D52<>"",VLOOKUP(H52,TABLEITEM,5,FALSE),"") -> กป. | K52: 41.6 | L52: =IF(D52<>"",VLOOKUP(H52,TABLEITEM,2,FALSE),"") | M52: =IF(D52<>"",VLOOKUP(H52,TABLEITEM,3,FALSE),"") -> สีสเปรย์ สีเขียว | N52: =INSTOCK!$I52*INSTOCK!$K52 -> 291.2
B53: 51 | C53: 43199 | D53: ยอดยกมา17 | H53: paint-210 | I53: 20 | J53: =IF(D53<>"",VLOOKUP(H53,TABLEITEM,5,FALSE),"") -> กป. | K53: 41.6 | L53: =IF(D53<>"",VLOOKUP(H53,TABLEITEM,2,FALSE),"") | M53: =IF(D53<>"",VLOOKUP(H53,TABLEITEM,3,FALSE),"") -> สีสเปรย์ สีดำ | N53: =INSTOCK!$I53*INSTOCK!$K53 -> 832
... B114: 112 | C114: 43199 | D114: ยอดยกมา17 | H114: keyFD-14 | I114: 338 | J114: =IF(D114<>"",VLOOKUP(H114,TABLEITEM,5,FALSE),"") -> EA | K114: 19 | L114: =IF(D114<>"",VLOOKUP(H114,TABLEITEM,2,FALSE),"") | M114: =IF(D114<>"",VLOOKUP(H114,TABLEITEM,3,FALSE),"") -> กุญแจหูกระเป๋าสแตนเลสตัวเล็กFD-14 | N114: =INSTOCK!$I114*INSTOCK!$K114 -> 6422
B115: 113 | C115: 43199 | D115: ยอดยกมา17 | H115: keyFD-13 | I115: 204 | J115: =IF(D115<>"",VLOOKUP(H115,TABLEITEM,5,FALSE),"") -> EA | L115: =IF(D115<>"",VLOOKUP(H115,TABLEITEM,2,FALSE),"") | M115: =IF(D115<>"",VLOOKUP(H115,TABLEITEM,3,FALSE),"") -> กุญแจหูกระเป๋าสแตนเลสตัวใหญ่FD-13 | N115: =INSTOCK!$I115*INSTOCK!$K115 -> 0
B116: 114 | C116: 43199 | D116: ยอดยกมา17 | H116: keyAB-301 | I116: 130 | J116: =IF(D116<>"",VLOOKUP(H116,TABLEITEM,5,FALSE),"") -> EA | K116: 90 | L116: =IF(D116<>"",VLOOKUP(H116,TABLEITEM,2,FALSE),"") | M116: =IF(D116<>"",VLOOKUP(H116,TABLEITEM,3,FALSE),"") -> DOOR LOCKER AB301-3-1 | N116: =INSTOCK!$I116*INSTOCK!$K116 -> 11700
B117: 115 | C117: 43199 | D117: ยอดยกมา17 | H117: key261-91H | I117: 10 | J117: =IF(D117<>"",VLOOKUP(H117,TABLEITEM,5,FALSE),"") -> EA | K117: 63.75 | L117: =IF(D117<>"",VLOOKUP(H117,TABLEITEM,2,FALSE),"") | M117: =IF(D117<>"",VLOOKUP(H117,TABLEITEM,3,FALSE),"") -> มือจับ 1A-261-91-H | N117: =INSTOCK!$I117*INSTOCK!$K117 -> 637.5
...

Sheet TABLEITEM
A1: INSTOCK
A2: NO. | B2: CODE | C2: GROUP | D2: LIST | E2: BRAND | F2: unit | G2: MAX | H2: SUM IN | I2: SUM OUT | J2: คงเหลือ | L2: GROUP | M2: กลุ่ม ประเภท
A3: 304 | B3: HP-30 | D3: โฮปลั๊ก 30 มิล | E3: BANDEX | F3: EA | G3: =MAX(IF(INSTOCK!$H$3:$H$6125=B3,INSTOCK!$K$3:$K$6125)) -> 0 | H3: {=SUM(IF(INSTOCK!$H$3:$H$6125=B3,INSTOCK!$I$3:$I$6125))} -> 52 | I3: =SUM(IF([3]!Table13[ID]=B3,[3]!Table13[QTY])) -> #ERROR! | J3: =TABLEITEM!$H$3:$H$2749-TABLEITEM!$I$3:$I$2749 -> #ERROR! | L3: Busbar | M3: บัสบาร์
A4: 303 | B4: HP-25 | D4: โฮปลั๊ก 25 มิล | E4: BANDEX | F4: EA | G4: {=MAX(IF(INSTOCK!$H$3:$H$6125=B4,INSTOCK!$K$3:$K$6125))} -> 0 | H4: {=SUM(IF(INSTOCK!$H$3:$H$6125=B4,INSTOCK!$I$3:$I$6125))} -> 70 | I4: =ARRAY_CONSTRAIN(ARRAYFORMULA(SUM(IF([3]!Table13[ID]=B4,[3]!Table13[QTY]))), 1, 1) -> #ERROR! | J4: =TABLEITEM!$H$3:$H$2749-TABLEITEM!$I$3:$I$2749 -> #ERROR! | L4: wire | M4: สายไฟ
A5: 302 | B5: HP-22 | D5: โฮปลั๊ก 22 มิล | E5: BANDEX | F5: EA | G5: {=MAX(IF(INSTOCK!$H$3:$H$6125=B5,INSTOCK!$K$3:$K$6125))} -> 0 | H5: {=SUM(IF(INSTOCK!$H$3:$H$6125=B5,INSTOCK!$I$3:$I$6125))} -> 76 | I5: =ARRAY_CONSTRAIN(ARRAYFORMULA(SUM(IF([3]!Table13[ID]=B5,[3]!Table13[QTY]))), 1, 1) -> #ERROR! | J5: =TABLEITEM!$H$3:$H$2749-TABLEITEM!$I$3:$I$2749 -> #ERROR! | L5: ACC | M5: ชิ้นส่วน
A6: 301 | B6: HP-10 | D6: โฮปลั๊ก 10 มิล | E6: BANDEX | F6: EA | G6: {=MAX(IF(INSTOCK!$H$3:$H$6125=B6,INSTOCK!$K$3:$K$6125))} -> 0.81965 | H6: {=SUM(IF(INSTOCK!$H$3:$H$6125=B6,INSTOCK!$I$3:$I$6125))} -> 200 | I6: =ARRAY_CONSTRAIN(ARRAYFORMULA(SUM(IF([3]!Table13[ID]=B6,[3]!Table13[QTY]))), 1, 1) -> #ERROR! | J6: =TABLEITEM!$H$3:$H$2749-TABLEITEM!$I$3:$I$2749 -> #ERROR! | L6: Support | M6: ลูกถ้วย&Support
B7: HEATER-CS-600 | D7: ฮิตเตอร์อินฟราเรด CS-600MM 1000W AC220V | E7: แสงชัย | F7: EA | G7: {=MAX(IF(INSTOCK!$H$3:$H$6125=B7,INSTOCK!$K$3:$K$6125))} -> 901 | H7: {=SUM(IF(INSTOCK!$H$3:$H$6125=B7,INSTOCK!$I$3:$I$6125))} -> 2 | I7: =ARRAY_CONSTRAIN(ARRAYFORMULA(SUM(IF([3]!Table13[ID]=B7,[3]!Table13[QTY]))), 1, 1) -> #ERROR! | J7: =TABLEITEM!$H$3:$H$2749-TABLEITEM!$I$3:$I$2749 -> #ERROR! | L7: Key | M7: กุญแจ
B8: TH-T18 3.6A | D8: โอเวอร์โหลด TH-T18 3.6A | E8: MITSU | F8: EA | G8: {=MAX(IF(INSTOCK!$H$3:$H$6125=B8,INSTOCK!$K$3:$K$6125))} -> 310 | H8: {=SUM(IF(INSTOCK!$H$3:$H$6125=B8,INSTOCK!$I$3:$I$6125))} -> 2 | I8: =ARRAY_CONSTRAIN(ARRAYFORMULA(SUM(IF([3]!Table13[ID]=B8,[3]!Table13[QTY]))), 1, 1) -> #ERROR! | J8: =TABLEITEM!$H$3:$H$2749-TABLEITEM!$I$3:$I$2749 -> #ERROR! | L8: KG. | M8: กิโลกรัม
B9: TH-T18 2.1A | D9: โอเวอร์โหลด TH-T18 2.1A | E9: MITSU | F9: EA | G9: {=MAX(IF(INSTOCK!$H$3:$H$6125=B9,INSTOCK!$K$3:$K$6125))} -> 310 | H9: {=SUM(IF(INSTOCK!$H$3:$H$6125=B9,INSTOCK!$I$3:$I$6125))} -> 3 | I9: =ARRAY_CONSTRAIN(ARRAYFORMULA(SUM(IF([3]!Table13[ID]=B9,[3]!Table13[QTY]))), 1, 1) -> #ERROR! | J9: =TABLEITEM!$H$3:$H$2749-TABLEITEM!$I$3:$I$2749 -> #ERROR!
A10: 161 | B10: ALCOHOL | D10: แอลกอฮอลดีพิเศษ | E10: ตะวัน | F10: กล. | G10: {=MAX(IF(INSTOCK!$H$3:$H$6125=B10,INSTOCK!$K$3:$K$6125))} -> 260 | H10: {=SUM(IF(INSTOCK!$H$3:$H$6125=B10,INSTOCK!$I$3:$I$6125))} -> 21 | I10: =ARRAY_CONSTRAIN(ARRAYFORMULA(SUM(IF([3]!Table13[ID]=B10,[3]!Table13[QTY]))), 1, 1) -> #ERROR! | J10: =TABLEITEM!$H$3:$H$2749-TABLEITEM!$I$3:$I$2749 -> #ERROR!
B11: ACC-อิฐตัวหนอน | D11: อิฐตัวหนอนแดง | F11: EA | G11: {=MAX(IF(INSTOCK!$H$3:$H$6125=B11,INSTOCK!$K$3:$K$6125))} -> 7.5 | H11: {=SUM(IF(INSTOCK!$H$3:$H$6125=B11,INSTOCK!$I$3:$I$6125))} -> 760 | I11: =ARRAY_CONSTRAIN(ARRAYFORMULA(SUM(IF([3]!Table13[ID]=B11,[3]!Table13[QTY]))), 1, 1) -> #ERROR! | J11: =TABLEITEM!$H$3:$H$2749-TABLEITEM!$I$3:$I$2749 -> #ERROR!
B12: AR6Q | D12: อาร์กอน ขนาด 6คิว | E12: UIG | F12: ท่อ | G12: {=MAX(IF(INSTOCK!$H$3:$H$6125=B12,INSTOCK!$K$3:$K$6125))} -> 600 | H12: {=SUM(IF(INSTOCK!$H$3:$H$6125=B12,INSTOCK!$I$3:$I$6125))} -> 142 | I12: =ARRAY_CONSTRAIN(ARRAYFORMULA(SUM(IF([3]!Table13[ID]=B12,[3]!Table13[QTY]))), 1, 1) -> #ERROR! | J12: =TABLEITEM!$H$3:$H$2749-TABLEITEM!$I$3:$I$2749 -> #ERROR!
B13: UVTNA250 | D13: อันเดอร์โวลเตจ UVTNA250-05SVR FOR NF32-SV-250-SV ขวา AC200-250V | E13: MITSU | F13: EA | G13: {=MAX(IF(INSTOCK!$H$3:$H$6125=B13,INSTOCK!$K$3:$K$6125))} -> 3103.65 | H13: {=SUM(IF(INSTOCK!$H$3:$H$6125=B13,INSTOCK!$I$3:$I$6125))} -> 1 | I13: =ARRAY_CONSTRAIN(ARRAYFORMULA(SUM(IF([3]!Table13[ID]=B13,[3]!Table13[QTY]))), 1, 1) -> #ERROR! | J13: =TABLEITEM!$H$3:$H$2749-TABLEITEM!$I$3:$I$2749 -> #ERROR!
B14: OFFICE-0000040 | D14: อะไหล่ม๊อบเพาเวอร์ BLACK MAN 10" | F14: EA | G14: {=MAX(IF(INSTOCK!$H$3:$H$6125=B14,INSTOCK!$K$3:$K$6125))} -> 95 | H14: {=SUM(IF(INSTOCK!$H$3:$H$6125=B14,INSTOCK!$I$3:$I$6125))} -> 1 | I14: =ARRAY_CONSTRAIN(ARRAYFORMULA(SUM(IF([3]!Table13[ID]=B14,[3]!Table13[QTY]))), 1, 1) -> #ERROR! | J14: =TABLEITEM!$H$3:$H$2749-TABLEITEM!$I$3:$I$2749 -> #ERROR!
B15: OFFICE-0003063 | D15: ไม้กวาดไนล่อน 35ซม. ด้ามยาว 120 ซม. | E15: NCL | F15: EA | G15: {=MAX(IF(INSTOCK!$H$3:$H$6125=B15,INSTOCK!$K$3:$K$6125))} -> 135.51 | H15: {=SUM(IF(INSTOCK!$H$3:$H$6125=B15,INSTOCK!$I$3:$I$6125))} -> 6 | I15: =ARRAY_CONSTRAIN(ARRAYFORMULA(SUM(IF([3]!Table13[ID]=B15,[3]!Table13[QTY]))), 1, 1) -> #ERROR! | J15: =TABLEITEM!$H$3:$H$2749-TABLEITEM!$I$3:$I$2749 -> #ERROR!
B16: TAP-4229 | D16: อะคริลิคโฟมเทป 12mmx10M #4229 | E16: 3M | F16: EA | G16: {=MAX(IF(INSTOCK!$H$3:$H$6125=B16,INSTOCK!$K$3:$K$6125))} -> 150 | H16: {=SUM(IF(INSTOCK!$H$3:$H$6125=B16,INSTOCK!$I$3:$I$6125))} -> 75 | I16: =ARRAY_CONSTRAIN(ARRAYFORMULA(SUM(IF([3]!Table13[ID]=B16,[3]!Table13[QTY]))), 1, 1) -> #ERROR! | J16: =TABLEITEM!$H$3:$H$2749-TABLEITEM!$I$3:$I$2749 -> #ERROR!
B17: TS2BIL2 | D17: ออดชนิดเสียงดังไม่ต่อเนื่องมีแลมป์ LED | E17: ธีรชัย | F17: EA | G17: {=MAX(IF(INSTOCK!$H$3:$H$6125=B17,INSTOCK!$K$3:$K$6125))} -> 14972 | H17: {=SUM(IF(INSTOCK!$H$3:$H$6125=B17,INSTOCK!$I$3:$I$6125))} -> 8 | I17: =ARRAY_CONSTRAIN(ARRAYFORMULA(SUM(IF([3]!Table13[ID]=B17,[3]!Table13[QTY]))), 1, 1) -> #ERROR! | J17: =TABLEITEM!$H$3:$H$2749-TABLEITEM!$I$3:$I$2749 -> #ERROR!
B18: OL148 | D18: ออกซิเจนเหลว ขนาด 148 คิว | E18: UIG | F18: ท่อ | G18: {=MAX(IF(INSTOCK!$H$3:$H$6125=B18,INSTOCK!$K$3:$K$6125))} -> 2960 | H18: {=SUM(IF(INSTOCK!$H$3:$H$6125=B18,INSTOCK!$I$3:$I$6125))} -> 29 | I18: =ARRAY_CONSTRAIN(ARRAYFORMULA(SUM(IF([3]!Table13[ID]=B18,[3]!Table13[QTY]))), 1, 1) -> #ERROR! | J18: =TABLEITEM!$H$3:$H$2749-TABLEITEM!$I$3:$I$2749 -> #ERROR!
B19: AT | D19: อแดปเตอร์ต่อสลัก | F19: EA | G19: {=MAX(IF(INSTOCK!$H$3:$H$6125=B19,INSTOCK!$K$3:$K$6125))} -> 0 | H19: {=SUM(IF(INSTOCK!$H$3:$H$6125=B19,INSTOCK!$I$3:$I$6125))} -> 0 | I19: =ARRAY_CONSTRAIN(ARRAYFORMULA(SUM(IF([3]!Table13[ID]=B19,[3]!Table13[QTY]))), 1, 1) -> #ERROR! | J19: =TABLEITEM!$H$3:$H$2749-TABLEITEM!$I$3:$I$2749 -> #ERROR!
B20: DP8SUS | D20: แหวนอีแปะ สแตนเลส M8 | E20: KM | F20: EA | G20: {=MAX(IF(INSTOCK!$H$3:$H$6125=B20,INSTOCK!$K$3:$K$6125))} -> 0.385 | H20: {=SUM(IF(INSTOCK!$H$3:$H$6125=B20,INSTOCK!$I$3:$I$6125))} -> 3000 | I20: =ARRAY_CONSTRAIN(ARRAYFORMULA(SUM(IF([3]!Table13[ID]=B20,[3]!Table13[QTY]))), 1, 1) -> #ERROR! | J20: =TABLEITEM!$H$3:$H$2749-TABLEITEM!$I$3:$I$2749 -> #ERROR!
B21: DP6SUS | D21: แหวนอีแปะ สแตนเลส M6 | E21: KM | F21: EA | G21: {=MAX(IF(INSTOCK!$H$3:$H$6125=B21,INSTOCK!$K$3:$K$6125))} -> 0.25 | H21: {=SUM(IF(INSTOCK!$H$3:$H$6125=B21,INSTOCK!$I$3:$I$6125))} -> 13000 | I21: =ARRAY_CONSTRAIN(ARRAYFORMULA(SUM(IF([3]!Table13[ID]=B21,[3]!Table13[QTY]))), 1, 1) -> #ERROR! | J21: =TABLEITEM!$H$3:$H$2749-TABLEITEM!$I$3:$I$2749 -> #ERROR!
B22: DP5SUS | D22: แหวนอีแปะ สแตนเลส M5 | E22: KM | F22: EA | G22: {=MAX(IF(INSTOCK!$H$3:$H$6125=B22,INSTOCK!$K$3:$K$6125))} -> 0.225 | H22: {=SUM(IF(INSTOCK!$H$3:$H$6125=B22,INSTOCK!$I$3:$I$6125))} -> 1000 | I22: =ARRAY_CONSTRAIN(ARRAYFORMULA(SUM(IF([3]!Table13[ID]=B22,[3]!Table13[QTY]))), 1, 1) -> #ERROR! | J22: =TABLEITEM!$H$3:$H$2749-TABLEITEM!$I$3:$I$2749 -> #ERROR!
B23: DP4SUS | D23: แหวนอีแปะ สแตนเลส M4 | E23: KM | F23: EA | G23: {=MAX(IF(INSTOCK!$H$3:$H$6125=B23,INSTOCK!$K$3:$K$6125))} -> 0 | H23: {=SUM(IF(INSTOCK!$H$3:$H$6125=B23,INSTOCK!$I$3:$I$6125))} -> 0 | I23: =ARRAY_CONSTRAIN(ARRAYFORMULA(SUM(IF([3]!Table13[ID]=B23,[3]!Table13[QTY]))), 1, 1) -> #ERROR! | J23: =TABLEITEM!$H$3:$H$2749-TABLEITEM!$I$3:$I$2749 -> #ERROR!
B24: DP10SUS | D24: แหวนอีแปะ SUS M10 | E24: AS | F24: EA | G24: {=MAX(IF(INSTOCK!$H$3:$H$6125=B24,INSTOCK!$K$3:$K$6125))} -> 2 | H24: {=SUM(IF(INSTOCK!$H$3:$H$6125=B24,INSTOCK!$I$3:$I$6125))} -> 360 | I24: =ARRAY_CONSTRAIN(ARRAYFORMULA(SUM(IF([3]!Table13[ID]=B24,[3]!Table13[QTY]))), 1, 1) -> #ERROR! | J24: =TABLEITEM!$H$3:$H$2749-TABLEITEM!$I$3:$I$2749 -> #ERROR!
B25: DP8 | D25: แหวนอีแปะ M8 ชุบขาว | E25: KM | F25: EA | G25: {=MAX(IF(INSTOCK!$H$3:$H$6125=B25,INSTOCK!$K$3:$K$6125))} -> 1.09 | H25: {=SUM(IF(INSTOCK!$H$3:$H$6125=B25,INSTOCK!$I$3:$I$6125))} -> 420000 | I25: =ARRAY_CONSTRAIN(ARRAYFORMULA(SUM(IF([3]!Table13[ID]=B25,[3]!Table13[QTY]))), 1, 1) -> #ERROR! | J25: =TABLEITEM!$H$3:$H$2749-TABLEITEM!$I$3:$I$2749 -> #ERROR!
B26: DP8HDG | D26: แหวนอีแปะ M8 HDG | E26: KM | F26: EA | G26: {=MAX(IF(INSTOCK!$H$3:$H$6125=B26,INSTOCK!$K$3:$K$6125))} -> 0.39 | H26: {=SUM(IF(INSTOCK!$H$3:$H$6125=B26,INSTOCK!$I$3:$I$6125))} -> 14000 | I26: =ARRAY_CONSTRAIN(ARRAYFORMULA(SUM(IF([3]!Table13[ID]=B26,[3]!Table13[QTY]))), 1, 1) -> #ERROR! | J26: =TABLEITEM!$H$3:$H$2749-TABLEITEM!$I$3:$I$2749 -> #ERROR!
B27: DP6 | D27: แหวนอีแปะ M6 ชุบขาว | E27: KM | F27: EA | G27: {=MAX(IF(INSTOCK!$H$3:$H$6125=B27,INSTOCK!$K$3:$K$6125))} -> 0.125 | H27: {=SUM(IF(INSTOCK!$H$3:$H$6125=B27,INSTOCK!$I$3:$I$6125))} -> 45000 | I27: =ARRAY_CONSTRAIN(ARRAYFORMULA(SUM(IF([3]!Table13[ID]=B27,[3]!Table13[QTY]))), 1, 1) -> #ERROR! | J27: =TABLEITEM!$H$3:$H$2749-TABLEITEM!$I$3:$I$2749 -> #ERROR!
B28: DP5Z | D28: แหวนอีแปะ M5 ชุบขาว | E28: KM | F28: EA | G28: {=MAX(IF(INSTOCK!$H$3:$H$6125=B28,INSTOCK!$K$3:$K$6125))} -> 0.055 | H28: {=SUM(IF(INSTOCK!$H$3:$H$6125=B28,INSTOCK!$I$3:$I$6125))} -> 2000 | I28: =ARRAY_CONSTRAIN(ARRAYFORMULA(SUM(IF([3]!Table13[ID]=B28,[3]!Table13[QTY]))), 1, 1) -> #ERROR! | J28: =TABLEITEM!$H$3:$H$2749-TABLEITEM!$I$3:$I$2749 -> #ERROR!
B29: DP4Z | D29: แหวนอีแปะ M4 ชุบขาว | E29: KM | F29: EA | G29: {=MAX(IF(INSTOCK!$H$3:$H$6125=B29,INSTOCK!$K$3:$K$6125))} -> 0.13 | H29: {=SUM(IF(INSTOCK!$H$3:$H$6125=B29,INSTOCK!$I$3:$I$6125))} -> 22000 | I29: =ARRAY_CONSTRAIN(ARRAYFORMULA(SUM(IF([3]!Table13[ID]=B29,[3]!Table13[QTY]))), 1, 1) -> #ERROR! | J29: =TABLEITEM!$H$3:$H$2749-TABLEITEM!$I$3:$I$2749 -> #ERROR!
B30: DP3Z | D30: แหวนอีแปะ M3 ชุบขาว | E30: KM | F30: EA | G30: {=MAX(IF(INSTOCK!$H$3:$H$6125=B30,INSTOCK!$K$3:$K$6125))} -> 0 | H30: {=SUM(IF(INSTOCK!$H$3:$H$6125=B30,INSTOCK!$I$3:$I$6125))} -> 0 | I30: =ARRAY_CONSTRAIN(ARRAYFORMULA(SUM(IF([3]!Table13[ID]=B30,[3]!Table13[QTY]))), 1, 1) -> #ERROR! | J30: =TABLEITEM!$H$3:$H$2749-TABLEITEM!$I$3:$I$2749 -> #ERROR!
B31: DP16 | D31: แหวนอีแปะ M16 ชุบขาว | E31: KM | F31: EA | G31: {=MAX(IF(INSTOCK!$H$3:$H$6125=B31,INSTOCK!$K$3:$K$6125))} -> 0.84 | H31: {=SUM(IF(INSTOCK!$H$3:$H$6125=B31,INSTOCK!$I$3:$I$6125))} -> 2400 | I31: =ARRAY_CONSTRAIN(ARRAYFORMULA(SUM(IF([3]!Table13[ID]=B31,[3]!Table13[QTY]))), 1, 1) -> #ERROR! | J31: =TABLEITEM!$H$3:$H$2749-TABLEITEM!$I$3:$I$2749 -> #ERROR!
... B59: PN4 | D59: แหวนพลาสติก M4 | E59: TPC | F59: EA | G59: {=MAX(IF(INSTOCK!$H$3:$H$6125=B59,INSTOCK!$K$3:$K$6125))} -> 0.6 | H59: {=SUM(IF(INSTOCK!$H$3:$H$6125=B59,INSTOCK!$I$3:$I$6125))} -> 1000 | I59: =ARRAY_CONSTRAIN(ARRAYFORMULA(SUM(IF([3]!Table13[ID]=B59,[3]!Table13[QTY]))), 1, 1) -> #ERROR! | J59: =TABLEITEM!$H$3:$H$2749-TABLEITEM!$I$3:$I$2749 -> #ERROR!
B60: MCW 8 | D60: แหวนฉิ่ง M8 | E60: GROWERMETAL | F60: EA | G60: =MAX(IF(INSTOCK!$H$3:$H$6125=B60,INSTOCK!$K$3:$K$6125)) -> 0 | H60: {=SUM(IF(INSTOCK!$H$3:$H$6125=B60,INSTOCK!$I$3:$I$6125))} -> 80000 | I60: =ARRAY_CONSTRAIN(ARRAYFORMULA(SUM(IF([3]!Table13[ID]=B60,[3]!Table13[QTY]))), 1, 1) -> #ERROR! | J60: =TABLEITEM!$H$3:$H$2749-TABLEITEM!$I$3:$I$2749 -> #ERROR!
B61: MCW 6 | D61: แหวนฉิ่ง M6 | E61: GROWERMETAL | F61: EA | G61: {=MAX(IF(INSTOCK!$H$3:$H$6125=B61,INSTOCK!$K$3:$K$6125))} -> 0.6 | H61: {=SUM(IF(INSTOCK!$H$3:$H$6125=B61,INSTOCK!$I$3:$I$6125))} -> 80000 | I61: =ARRAY_CONSTRAIN(ARRAYFORMULA(SUM(IF([3]!Table13[ID]=B61,[3]!Table13[QTY]))), 1, 1) -> #ERROR! | J61: =TABLEITEM!$H$3:$H$2749-TABLEITEM!$I$3:$I$2749 -> #ERROR!
B62: MCW 12 | D62: แหวนฉิ่ง M12 | E62: GROWERMETAL | F62: EA | G62: {=MAX(IF(INSTOCK!$H$3:$H$6125=B62,INSTOCK!$K$3:$K$6125))} -> 2.7 | H62: {=SUM(IF(INSTOCK!$H$3:$H$6125=B62,INSTOCK!$I$3:$I$6125))} -> 80000 | I62: =ARRAY_CONSTRAIN(ARRAYFORMULA(SUM(IF([3]!Table13[ID]=B62,[3]!Table13[QTY]))), 1, 1) -> #ERROR! | J62: =TABLEITEM!$H$3:$H$2749-TABLEITEM!$I$3:$I$2749 -> #ERROR!
B63: MCW 10 | D63: แหวนฉิ่ง M10 | E63: GROWERMETAL | F63: EA | G63: {=MAX(IF(INSTOCK!$H$3:$H$6125=B63,INSTOCK!$K$3:$K$6125))} -> 1.6 | H63: {=SUM(IF(INSTOCK!$H$3:$H$6125=B63,INSTOCK!$I$3:$I$6125))} -> 80000 | I63: =ARRAY_CONSTRAIN(ARRAYFORMULA(SUM(IF([3]!Table13[ID]=B63,[3]!Table13[QTY]))), 1, 1) -> #ERROR! | J63: =TABLEITEM!$H$3:$H$2749-TABLEITEM!$I$3:$I$2749 -> #ERROR!
B64: SRST6 | D64: แหวนจักร M6 | E64: KM | F64: EA | G64: {=MAX(IF(INSTOCK!$H$3:$H$6125=B64,INSTOCK!$K$3:$K$6125))} -> 0.19 | H64: {=SUM(IF(INSTOCK!$H$3:$H$6125=B64,INSTOCK!$I$3:$I$6125))} -> 6000 | I64: =ARRAY_CONSTRAIN(ARRAYFORMULA(SUM(IF([3]!Table13[ID]=B64,[3]!Table13[QTY]))), 1, 1) -> #ERROR! | J64: =TABLEITEM!$H$3:$H$2749-TABLEITEM!$I$3:$I$2749 -> #ERROR!
B65: ACC-หินเกล็ด | D65: หินเกล็ด ใหญ่ | F65: EA | G65: {=MAX(IF(INSTOCK!$H$3:$H$6125=B65,INSTOCK!$K$3:$K$6125))} -> 3000 | H65: {=SUM(IF(INSTOCK!$H$3:$H$6125=B65,INSTOCK!$I$3:$I$6125))} -> 1 | I65: =ARRAY_CONSTRAIN(ARRAYFORMULA(SUM(IF([3]!Table13[ID]=B65,[3]!Table13[QTY]))), 1, 1) -> #ERROR! | J65: =TABLEITEM!$H$3:$H$2749-TABLEITEM!$I$3:$I$2749 -> #ERROR!
A66: 453 | B66: 218-FB | D66: หางปลาหัวเสียบก้านไม้ขีด 218-FD สีน้ำเงิน | E66: T.LUG | F66: EA | G66: {=MAX(IF(INSTOCK!$H$3:$H$6125=B66,INSTOCK!$K$3:$K$6125))} -> 3.25 | H66: {=SUM(IF(INSTOCK!$H$3:$H$6125=B66,INSTOCK!$I$3:$I$6125))} -> 1000 | I66: =ARRAY_CONSTRAIN(ARRAYFORMULA(SUM(IF([3]!Table13[ID]=B66,[3]!Table13[QTY]))), 1, 1) -> #ERROR! | J66: =TABLEITEM!$H$3:$H$2749-TABLEITEM!$I$3:$I$2749 -> #ERROR!
A67: 459 | B67: KT22-16 | D67: หางปลาเสียบแบนสีแดง KT22-16 | E67: T.LUG | F67: EA | G67: {=MAX(IF(INSTOCK!$H$3:$H$6125=B67,INSTOCK!$K$3:$K$6125))} -> 0 | H67: {=SUM(IF(INSTOCK!$H$3:$H$6125=B67,INSTOCK!$I$3:$I$6125))} -> 900 | I67: =ARRAY_CONSTRAIN(ARRAYFORMULA(SUM(IF([3]!Table13[ID]=B67,[3]!Table13[QTY]))), 1, 1) -> #ERROR! | J67: =TABLEITEM!$H$3:$H$2749-TABLEITEM!$I$3:$I$2749 -> #ERROR!
...

Sheet REPORTIN
I1: ID | J1: BS
A2: SUPPLIER | B2: (All) | I2: LIST | J2: (All)
A3: IV No. | B3: IV6103151
A4: PO No. | B4: (All) | M4: Values
A5: PC Job | B5: (Multiple Items) | I5: SUPPLIER | J5: DATE | K5: IV No. | L5: UNIT/Price | M5: Sum of QTY | N5: Sum of Total
I6: (blank) | J6: 43199 | K6: ยอดยกมา17 | L6: 40 | M6: 360 | N6: 14400
C7: Values | I7: บอร์เนียว | J7: 43132 | K7: 0418G00694 | L7: 45 | M7: 400 | N7: 18000
A8: ID | B8: LIST | C8: Average of UNIT/Price | D8: Sum of QTY | E8: Sum of Total | J8: 43161 | K8: 0418G01413 | L8: 45 | M8: 300 | N8: 13500
A9: BAR 100x10 | B9: บัสบาร์ทองแดง 100x10 | C9: 2145.6 | D9: 25 | E9: 53640 | J9: 43164 | K9: 0418G01472 | L9: 45 | M9: 100 | N9: 4500
A10: BAR 15X3 | B10: บัสบาร์ทองแดง 15x3 | C10: 100.8 | D10: 100 | E10: 10080 | J10: 43207 | K10: 418030840 | L10: 45 | M10: 400 | N10: 18000
A11: Grand Total | C11: 1123.2 | D11: 125 | E11: 63720 | J11: 43237 | K11: 418040607 | L11: 45 | M11: 400 | N11: 18000
J12: 43262 | K12: 418047550 | L12: 45 | M12: 400 | N12: 18000
J13: 43304 | K13: 418064683 | L13: 45 | M13: 400 | N13: 18000
J14: 43348 | K14: 418074872 | L14: 45 | M14: 400 | N14: 18000
J15: 43405 | K15: 0418G07328 | L15: 45 | M15: 400 | N15: 18000
J16: 43543 | K16: 419026590 | L16: 45 | M16: 400 | N16: 18000
J17: 43600 | K17: 419042156 | L17: 45 | M17: 400 | N17: 18000
J18: 43654 | K18: 419058888 | L18: 45 | M18: 400 | N18: 18000
J19: 43719 | K19: 419079291 | L19: 45 | M19: 400 | N19: 18000
J20: 43770 | K20: 0419G07266 | L20: 45 | M20: 400 | N20: 18000
I21: Grand Total | M21: 5560 | N21: 248400
